<?xml version="1.0"?>
<robot name="mybot" xmlns:xacro="http://www.ros.org/wiki/xacro">

  <!-- Base footprint -->
  <link name="base_footprint"/>
  <joint name="base_footprint_joint" type="fixed">
    <parent link="base_footprint"/>
    <child link="base_link"/>
    <origin xyz="0 0 0.2205" rpy="0 0 0"/>
  </joint>

  <link name="base_link">
    <inertial>
       <origin xyz="0.0 0.0 0.0" rpy="0.0 0.0 0.0"/>
       <mass value="5.0"/>
       <inertia ixx="0.0" ixy="0.0" ixz="0.0" iyy="0.0" iyz="0.0" izz="0.0"/>
    </inertial>
    <visual>
      <geometry>
        <cylinder length="0.441" radius="0.20"/>
      </geometry>
      <origin xyz="0 0 0" rpy="0 0 0"/>
      <material name="grey"><color rgba="0.5 0.5 0.5 1"/></material>
    </visual>   
    <collision>
      <origin xyz="0.0 0.0 0.0" rpy="0.0 0.0 0.0"/>
      <geometry>
        <cylinder length="0.441" radius="0.20"/>
      </geometry>
    </collision>  
  </link>


  <!-- Left Wheel -->
  <link name="left_wheel">  
    <inertial>
      <origin xyz="0.0 0.0 0.0" rpy="0.0 1.5707 1.5707"/>
      <mass value="5.0"/>
      <inertia ixx="0.1" ixy="0.0" ixz="0.0" iyy="0.1" iyz="0.0" izz="0.1"/>
    </inertial>
    <visual>
      <geometry>
        <cylinder length="0.026" radius="0.0325"/>
      </geometry>
      <origin xyz="0 0 0" rpy="0 0 0"/>
      <material name="black"><color rgba="0 0 0 1"/></material>
    </visual>
    <collision>
      <origin xyz="0.0 0.0 0.0" rpy="0.0 0.0 0.0"/>
      <geometry>
        <cylinder length="0.026" radius="0.0325"/>
      </geometry>
    </collision>    
  </link>
  <joint name="left_wheel_joint" type="continuous">
    <parent link="base_link"/>
    <child link="left_wheel"/>
    <origin xyz="0 0.1525 -0.253" rpy="0.0 1.5705 1.5705"/>
    <axis xyz="0 0 1"/>
  </joint>



  <!-- Right Wheel -->
  <link name="right_wheel">  
    <inertial>
       <origin xyz="0.0 0.0 0.0" rpy="0.0 0.0 0.0"/>
       <mass value="5.0"/>
       <inertia ixx="0.1" ixy="0.0" ixz="0.0" iyy="0.1" iyz="0.0" izz="0.1"/>
    </inertial>
    <visual>
      <geometry>
        <cylinder length="0.026" radius="0.0325"/>
      </geometry>
      <origin xyz="0 0 0" rpy="0 0 0"/>
      <material name="black"/>
    </visual>
    <collision>
      <origin xyz="0.0 0.0 0.0" rpy="0.0 0.0 0.0"/>
      <geometry>
        <cylinder length="0.026" radius="0.0325"/>
      </geometry>
    </collision>
  </link>
  <joint name="right_wheel_joint" type="continuous">
    <parent link="base_link"/>
    <child link="right_wheel"/>
    <origin xyz="0 -0.1525 -0.253" rpy="0.0 1.5705 1.5705"/>
    <axis xyz="0 0 1"/>
  </joint>



  <!-- Front Caster Wheel -->
  <link name="front_caster_wheel">
    <inertial>
      <origin xyz="0.0 0.0 0.0" rpy="0.0 0.0 0.0"/>
      <mass value="0.0"/>
      <inertia ixx="0.0" ixy="0.0" ixz="0.0" iyy="0.0" iyz="0.0" izz="0.0"/>
    </inertial>
    <visual>
      <origin xyz="0.0 0.0 0.0" rpy="0.0 0.0 0.0"/>
      <geometry>
        <sphere radius="0.0325"/>
      </geometry>
      <material name="silver"><color rgba="0.75 0.75 0.75 1"/></material>
    </visual>
    <collision>
      <origin xyz="0.0 0.0 0.0" rpy="0.0 0.0 0.0"/>
      <geometry>
        <sphere radius="0.0325"/>
      </geometry>
    </collision>
  </link>
  <joint name="front_caster_joint" type="fixed">
    <parent link="base_link"/>
    <child link="front_caster_wheel"/>
    <origin xyz="0.1525025 0 -0.253" rpy="0 0 0"/>
    <axis xyz="0.0 0.0 0.0"/>
  </joint>



  <!-- Rear Caster Wheel -->
  <link name="rear_caster_wheel">
    <inertial>
      <origin xyz="0.0 0.0 0.0" rpy="0.0 0.0 0.0"/>
      <mass value="0.0"/>
      <inertia ixx="0.0" ixy="0.0" ixz="0.0" iyy="0.0" iyz="0.0" izz="0.0"/>
    </inertial>
    <visual>
      <origin xyz="0.0 0.0 0.0" rpy="0.0 0.0 0.0"/>
      <geometry>
        <sphere radius="0.0325"/>
      </geometry>
      <material name="silver"/>
    </visual>
    <collision>
      <origin xyz="0.0 0.0 0.0" rpy="0.0 0.0 0.0"/>
      <geometry>
        <sphere radius="0.0325"/>
      </geometry>
    </collision>
  </link>
  <joint name="rear_caster_joint" type="fixed">
    <parent link="base_link"/>
    <child link="rear_caster_wheel"/>
    <origin xyz="-0.1525025 0 -0.253" rpy="0 0 0"/>
    <axis xyz="0.0 0.0 0.0"/>
  </joint>



<!-- IMU -->
    <link name="imu_link">
        <collision>
        <origin xyz="0 0 0.1" rpy="0 0 0"/>
        <geometry>
            <box size="0.02 0.02 0.02"/>
        </geometry>
        </collision>

        <visual>
        <origin xyz="0 0 0.1" rpy="0 0 0"/>
        <geometry>
            <box size="0.02 0.02 0.02"/>
        </geometry>
        <material name="green"><color rgba="0 1 0 1"/></material>
        </visual>

        <inertial>
        <origin xyz="0 0 1" rpy="0 0 0"/>
        <mass value="1"/>
        <inertia
            ixx="1.0" ixy="0.0" ixz="0.0"
            iyy="1.0" iyz="0.0"
            izz="1.0"/>
        </inertial>
    </link>
  <joint name="imu_joint" type="fixed">
    <parent link="base_link"/>
    <child link="imu_link"/>
    <origin xyz="0 0 -0.2" rpy="0 0 0"/>
  </joint>


<link name="lidar_link">
  <inertial>
     <origin xyz="0.0 0.0 0.0" rpy="0.0 0.0 0.0"/>
     <mass value="0.1"/>
     <inertia ixx="0.0" ixy="0.0" ixz="0.0" iyy="0.0" iyz="0.0" izz="0.0"/>
  </inertial>
  <visual>
    <origin xyz="0 0 0" rpy="0 0 0"/>
    <geometry>
      <cylinder length="0.055" radius="0.036"/>
    </geometry>
    <material name="green"><color rgba="0 1 0 1"/></material>
  </visual>
  <collision>
    <origin xyz="0 0 0" rpy="0 0 0"/>
    <geometry>
      <cylinder length="0.055" radius="0.036"/>
    </geometry>
  </collision>
</link>
<joint name="lidar_joint" type="fixed">
  <parent link="base_link"/>
  <child link="lidar_link"/>
  <origin xyz="0 0 0.248" rpy="0 0 0"/>
</joint>



  <!-- LiDAR -->
  <link name="laser">
  </link>
  <joint name="laser_data_joint" type="fixed">
    <parent link="lidar_link"/>
    <child link="laser"/>
    <origin xyz="0 0 0" rpy="0 0 0"/>
  </joint>
  
</robot>



